2021-11-07 20:50:26,551  django.request ERROR    <--> Internal Server Error: /sort_most_viewedr_up/favicon.ico
Traceback (most recent call last):
  File "/home/yaroslav/.local/lib/python3.8/site-packages/django/core/handlers/exception.py", line 47, in inner
    response = get_response(request)
  File "/home/yaroslav/.local/lib/python3.8/site-packages/django/core/handlers/base.py", line 181, in _get_response
    response = wrapped_callback(request, *callback_args, **callback_kwargs)
  File "/home/yaroslav/.local/lib/python3.8/site-packages/django/views/generic/base.py", line 70, in view
    return self.dispatch(request, *args, **kwargs)
  File "/home/yaroslav/.local/lib/python3.8/site-packages/django/views/generic/base.py", line 98, in dispatch
    return handler(request, *args, **kwargs)
  File "/home/yaroslav/.local/lib/python3.8/site-packages/django/views/generic/list.py", line 157, in get
    context = self.get_context_data()
  File "/home/yaroslav/Programming/Python/Django/StoreProject/market/store/services/order.py", line 28, in get_context_data
    context = super().get_context_data(**kwargs)  # like dynamic list
  File "/home/yaroslav/.local/lib/python3.8/site-packages/django/views/generic/list.py", line 119, in get_context_data
    paginator, page, queryset, is_paginated = self.paginate_queryset(queryset, page_size)
  File "/home/yaroslav/.local/lib/python3.8/site-packages/django/views/generic/list.py", line 69, in paginate_queryset
    page = paginator.page(page_number)
  File "/home/yaroslav/.local/lib/python3.8/site-packages/django/core/paginator.py", line 76, in page
    number = self.validate_number(number)
  File "/home/yaroslav/.local/lib/python3.8/site-packages/django/core/paginator.py", line 54, in validate_number
    if number > self.num_pages:
  File "/home/yaroslav/.local/lib/python3.8/site-packages/django/utils/functional.py", line 48, in __get__
    res = instance.__dict__[self.name] = self.func(instance)
  File "/home/yaroslav/.local/lib/python3.8/site-packages/django/core/paginator.py", line 103, in num_pages
    if self.count == 0 and not self.allow_empty_first_page:
  File "/home/yaroslav/.local/lib/python3.8/site-packages/django/utils/functional.py", line 48, in __get__
    res = instance.__dict__[self.name] = self.func(instance)
  File "/home/yaroslav/.local/lib/python3.8/site-packages/django/core/paginator.py", line 98, in count
    return len(self.object_list)
TypeError: object of type 'NoneType' has no len()
2021-11-07 20:57:06,961  django.request ERROR    <--> Internal Server Error: /sort_most_viewed_up/home
Traceback (most recent call last):
  File "/home/yaroslav/.local/lib/python3.8/site-packages/django/core/handlers/exception.py", line 47, in inner
    response = get_response(request)
  File "/home/yaroslav/.local/lib/python3.8/site-packages/django/core/handlers/base.py", line 204, in _get_response
    response = response.render()
  File "/home/yaroslav/.local/lib/python3.8/site-packages/django/template/response.py", line 105, in render
    self.content = self.rendered_content
  File "/home/yaroslav/.local/lib/python3.8/site-packages/django/template/response.py", line 83, in rendered_content
    return template.render(context, self._request)
  File "/home/yaroslav/.local/lib/python3.8/site-packages/django/template/backends/django.py", line 61, in render
    return self.template.render(context)
  File "/home/yaroslav/.local/lib/python3.8/site-packages/django/template/base.py", line 170, in render
    return self._render(context)
  File "/home/yaroslav/.local/lib/python3.8/site-packages/django/template/base.py", line 162, in _render
    return self.nodelist.render(context)
  File "/home/yaroslav/.local/lib/python3.8/site-packages/django/template/base.py", line 938, in render
    bit = node.render_annotated(context)
  File "/home/yaroslav/.local/lib/python3.8/site-packages/django/template/base.py", line 905, in render_annotated
    return self.render(context)
  File "/home/yaroslav/.local/lib/python3.8/site-packages/django/template/loader_tags.py", line 150, in render
    return compiled_parent._render(context)
  File "/home/yaroslav/.local/lib/python3.8/site-packages/django/template/base.py", line 162, in _render
    return self.nodelist.render(context)
  File "/home/yaroslav/.local/lib/python3.8/site-packages/django/template/base.py", line 938, in render
    bit = node.render_annotated(context)
  File "/home/yaroslav/.local/lib/python3.8/site-packages/django/template/base.py", line 905, in render_annotated
    return self.render(context)
  File "/home/yaroslav/.local/lib/python3.8/site-packages/django/template/loader_tags.py", line 150, in render
    return compiled_parent._render(context)
  File "/home/yaroslav/.local/lib/python3.8/site-packages/django/template/base.py", line 162, in _render
    return self.nodelist.render(context)
  File "/home/yaroslav/.local/lib/python3.8/site-packages/django/template/base.py", line 938, in render
    bit = node.render_annotated(context)
  File "/home/yaroslav/.local/lib/python3.8/site-packages/django/template/base.py", line 905, in render_annotated
    return self.render(context)
  File "/home/yaroslav/.local/lib/python3.8/site-packages/django/template/loader_tags.py", line 62, in render
    result = block.nodelist.render(context)
  File "/home/yaroslav/.local/lib/python3.8/site-packages/django/template/base.py", line 938, in render
    bit = node.render_annotated(context)
  File "/home/yaroslav/.local/lib/python3.8/site-packages/django/template/base.py", line 905, in render_annotated
    return self.render(context)
  File "/home/yaroslav/.local/lib/python3.8/site-packages/django/template/defaulttags.py", line 446, in render
    url = reverse(view_name, args=args, kwargs=kwargs, current_app=current_app)
  File "/home/yaroslav/.local/lib/python3.8/site-packages/django/urls/base.py", line 86, in reverse
    return resolver._reverse_with_prefix(view, prefix, *args, **kwargs)
  File "/home/yaroslav/.local/lib/python3.8/site-packages/django/urls/resolvers.py", line 694, in _reverse_with_prefix
    raise NoReverseMatch(msg)
django.urls.exceptions.NoReverseMatch: Reverse for 'sort_most_viewed_up' with keyword arguments '{'place': ''}' not found. 1 pattern(s) tried: ['sort_most_viewed_up/(?P<place>[^/]+)$']
2021-11-07 20:57:11,254  django.request ERROR    <--> Internal Server Error: /sort_most_viewed_up/home
Traceback (most recent call last):
  File "/home/yaroslav/.local/lib/python3.8/site-packages/django/core/handlers/exception.py", line 47, in inner
    response = get_response(request)
  File "/home/yaroslav/.local/lib/python3.8/site-packages/django/core/handlers/base.py", line 204, in _get_response
    response = response.render()
  File "/home/yaroslav/.local/lib/python3.8/site-packages/django/template/response.py", line 105, in render
    self.content = self.rendered_content
  File "/home/yaroslav/.local/lib/python3.8/site-packages/django/template/response.py", line 83, in rendered_content
    return template.render(context, self._request)
  File "/home/yaroslav/.local/lib/python3.8/site-packages/django/template/backends/django.py", line 61, in render
    return self.template.render(context)
  File "/home/yaroslav/.local/lib/python3.8/site-packages/django/template/base.py", line 170, in render
    return self._render(context)
  File "/home/yaroslav/.local/lib/python3.8/site-packages/django/template/base.py", line 162, in _render
    return self.nodelist.render(context)
  File "/home/yaroslav/.local/lib/python3.8/site-packages/django/template/base.py", line 938, in render
    bit = node.render_annotated(context)
  File "/home/yaroslav/.local/lib/python3.8/site-packages/django/template/base.py", line 905, in render_annotated
    return self.render(context)
  File "/home/yaroslav/.local/lib/python3.8/site-packages/django/template/loader_tags.py", line 150, in render
    return compiled_parent._render(context)
  File "/home/yaroslav/.local/lib/python3.8/site-packages/django/template/base.py", line 162, in _render
    return self.nodelist.render(context)
  File "/home/yaroslav/.local/lib/python3.8/site-packages/django/template/base.py", line 938, in render
    bit = node.render_annotated(context)
  File "/home/yaroslav/.local/lib/python3.8/site-packages/django/template/base.py", line 905, in render_annotated
    return self.render(context)
  File "/home/yaroslav/.local/lib/python3.8/site-packages/django/template/loader_tags.py", line 150, in render
    return compiled_parent._render(context)
  File "/home/yaroslav/.local/lib/python3.8/site-packages/django/template/base.py", line 162, in _render
    return self.nodelist.render(context)
  File "/home/yaroslav/.local/lib/python3.8/site-packages/django/template/base.py", line 938, in render
    bit = node.render_annotated(context)
  File "/home/yaroslav/.local/lib/python3.8/site-packages/django/template/base.py", line 905, in render_annotated
    return self.render(context)
  File "/home/yaroslav/.local/lib/python3.8/site-packages/django/template/loader_tags.py", line 62, in render
    result = block.nodelist.render(context)
  File "/home/yaroslav/.local/lib/python3.8/site-packages/django/template/base.py", line 938, in render
    bit = node.render_annotated(context)
  File "/home/yaroslav/.local/lib/python3.8/site-packages/django/template/base.py", line 905, in render_annotated
    return self.render(context)
  File "/home/yaroslav/.local/lib/python3.8/site-packages/django/template/defaulttags.py", line 446, in render
    url = reverse(view_name, args=args, kwargs=kwargs, current_app=current_app)
  File "/home/yaroslav/.local/lib/python3.8/site-packages/django/urls/base.py", line 86, in reverse
    return resolver._reverse_with_prefix(view, prefix, *args, **kwargs)
  File "/home/yaroslav/.local/lib/python3.8/site-packages/django/urls/resolvers.py", line 694, in _reverse_with_prefix
    raise NoReverseMatch(msg)
django.urls.exceptions.NoReverseMatch: Reverse for 'sort_most_viewed_up' with keyword arguments '{'place': ''}' not found. 1 pattern(s) tried: ['sort_most_viewed_up/(?P<place>[^/]+)$']
2021-11-07 20:57:31,677  django.request ERROR    <--> Internal Server Error: /sort_most_viewed_up/home
Traceback (most recent call last):
  File "/home/yaroslav/.local/lib/python3.8/site-packages/django/core/handlers/exception.py", line 47, in inner
    response = get_response(request)
  File "/home/yaroslav/.local/lib/python3.8/site-packages/django/core/handlers/base.py", line 204, in _get_response
    response = response.render()
  File "/home/yaroslav/.local/lib/python3.8/site-packages/django/template/response.py", line 105, in render
    self.content = self.rendered_content
  File "/home/yaroslav/.local/lib/python3.8/site-packages/django/template/response.py", line 83, in rendered_content
    return template.render(context, self._request)
  File "/home/yaroslav/.local/lib/python3.8/site-packages/django/template/backends/django.py", line 61, in render
    return self.template.render(context)
  File "/home/yaroslav/.local/lib/python3.8/site-packages/django/template/base.py", line 170, in render
    return self._render(context)
  File "/home/yaroslav/.local/lib/python3.8/site-packages/django/template/base.py", line 162, in _render
    return self.nodelist.render(context)
  File "/home/yaroslav/.local/lib/python3.8/site-packages/django/template/base.py", line 938, in render
    bit = node.render_annotated(context)
  File "/home/yaroslav/.local/lib/python3.8/site-packages/django/template/base.py", line 905, in render_annotated
    return self.render(context)
  File "/home/yaroslav/.local/lib/python3.8/site-packages/django/template/loader_tags.py", line 150, in render
    return compiled_parent._render(context)
  File "/home/yaroslav/.local/lib/python3.8/site-packages/django/template/base.py", line 162, in _render
    return self.nodelist.render(context)
  File "/home/yaroslav/.local/lib/python3.8/site-packages/django/template/base.py", line 938, in render
    bit = node.render_annotated(context)
  File "/home/yaroslav/.local/lib/python3.8/site-packages/django/template/base.py", line 905, in render_annotated
    return self.render(context)
  File "/home/yaroslav/.local/lib/python3.8/site-packages/django/template/loader_tags.py", line 150, in render
    return compiled_parent._render(context)
  File "/home/yaroslav/.local/lib/python3.8/site-packages/django/template/base.py", line 162, in _render
    return self.nodelist.render(context)
  File "/home/yaroslav/.local/lib/python3.8/site-packages/django/template/base.py", line 938, in render
    bit = node.render_annotated(context)
  File "/home/yaroslav/.local/lib/python3.8/site-packages/django/template/base.py", line 905, in render_annotated
    return self.render(context)
  File "/home/yaroslav/.local/lib/python3.8/site-packages/django/template/loader_tags.py", line 62, in render
    result = block.nodelist.render(context)
  File "/home/yaroslav/.local/lib/python3.8/site-packages/django/template/base.py", line 938, in render
    bit = node.render_annotated(context)
  File "/home/yaroslav/.local/lib/python3.8/site-packages/django/template/base.py", line 905, in render_annotated
    return self.render(context)
  File "/home/yaroslav/.local/lib/python3.8/site-packages/django/template/defaulttags.py", line 446, in render
    url = reverse(view_name, args=args, kwargs=kwargs, current_app=current_app)
  File "/home/yaroslav/.local/lib/python3.8/site-packages/django/urls/base.py", line 86, in reverse
    return resolver._reverse_with_prefix(view, prefix, *args, **kwargs)
  File "/home/yaroslav/.local/lib/python3.8/site-packages/django/urls/resolvers.py", line 694, in _reverse_with_prefix
    raise NoReverseMatch(msg)
django.urls.exceptions.NoReverseMatch: Reverse for 'sort_most_viewed_up' with keyword arguments '{'place': ''}' not found. 1 pattern(s) tried: ['sort_most_viewed_up/(?P<place>[^/]+)$']
2021-11-07 21:00:12,998  django.request ERROR    <--> Internal Server Error: /sort_most_viewed_up/favicon.ico
Traceback (most recent call last):
  File "/home/yaroslav/.local/lib/python3.8/site-packages/django/core/handlers/exception.py", line 47, in inner
    response = get_response(request)
  File "/home/yaroslav/.local/lib/python3.8/site-packages/django/core/handlers/base.py", line 181, in _get_response
    response = wrapped_callback(request, *callback_args, **callback_kwargs)
  File "/home/yaroslav/.local/lib/python3.8/site-packages/django/views/generic/base.py", line 70, in view
    return self.dispatch(request, *args, **kwargs)
  File "/home/yaroslav/.local/lib/python3.8/site-packages/django/views/generic/base.py", line 98, in dispatch
    return handler(request, *args, **kwargs)
  File "/home/yaroslav/.local/lib/python3.8/site-packages/django/views/generic/list.py", line 157, in get
    context = self.get_context_data()
  File "/home/yaroslav/Programming/Python/Django/StoreProject/market/store/services/order.py", line 27, in get_context_data
    context = super().get_context_data(**kwargs)  # like dynamic list
  File "/home/yaroslav/.local/lib/python3.8/site-packages/django/views/generic/list.py", line 119, in get_context_data
    paginator, page, queryset, is_paginated = self.paginate_queryset(queryset, page_size)
  File "/home/yaroslav/.local/lib/python3.8/site-packages/django/views/generic/list.py", line 69, in paginate_queryset
    page = paginator.page(page_number)
  File "/home/yaroslav/.local/lib/python3.8/site-packages/django/core/paginator.py", line 76, in page
    number = self.validate_number(number)
  File "/home/yaroslav/.local/lib/python3.8/site-packages/django/core/paginator.py", line 54, in validate_number
    if number > self.num_pages:
  File "/home/yaroslav/.local/lib/python3.8/site-packages/django/utils/functional.py", line 48, in __get__
    res = instance.__dict__[self.name] = self.func(instance)
  File "/home/yaroslav/.local/lib/python3.8/site-packages/django/core/paginator.py", line 103, in num_pages
    if self.count == 0 and not self.allow_empty_first_page:
  File "/home/yaroslav/.local/lib/python3.8/site-packages/django/utils/functional.py", line 48, in __get__
    res = instance.__dict__[self.name] = self.func(instance)
  File "/home/yaroslav/.local/lib/python3.8/site-packages/django/core/paginator.py", line 98, in count
    return len(self.object_list)
TypeError: object of type 'NoneType' has no len()
2021-11-07 21:00:17,886  django.request ERROR    <--> Internal Server Error: /sort_most_viewed_down/home
Traceback (most recent call last):
  File "/home/yaroslav/.local/lib/python3.8/site-packages/django/core/handlers/exception.py", line 47, in inner
    response = get_response(request)
  File "/home/yaroslav/.local/lib/python3.8/site-packages/django/core/handlers/base.py", line 204, in _get_response
    response = response.render()
  File "/home/yaroslav/.local/lib/python3.8/site-packages/django/template/response.py", line 105, in render
    self.content = self.rendered_content
  File "/home/yaroslav/.local/lib/python3.8/site-packages/django/template/response.py", line 83, in rendered_content
    return template.render(context, self._request)
  File "/home/yaroslav/.local/lib/python3.8/site-packages/django/template/backends/django.py", line 61, in render
    return self.template.render(context)
  File "/home/yaroslav/.local/lib/python3.8/site-packages/django/template/base.py", line 170, in render
    return self._render(context)
  File "/home/yaroslav/.local/lib/python3.8/site-packages/django/template/base.py", line 162, in _render
    return self.nodelist.render(context)
  File "/home/yaroslav/.local/lib/python3.8/site-packages/django/template/base.py", line 938, in render
    bit = node.render_annotated(context)
  File "/home/yaroslav/.local/lib/python3.8/site-packages/django/template/base.py", line 905, in render_annotated
    return self.render(context)
  File "/home/yaroslav/.local/lib/python3.8/site-packages/django/template/loader_tags.py", line 150, in render
    return compiled_parent._render(context)
  File "/home/yaroslav/.local/lib/python3.8/site-packages/django/template/base.py", line 162, in _render
    return self.nodelist.render(context)
  File "/home/yaroslav/.local/lib/python3.8/site-packages/django/template/base.py", line 938, in render
    bit = node.render_annotated(context)
  File "/home/yaroslav/.local/lib/python3.8/site-packages/django/template/base.py", line 905, in render_annotated
    return self.render(context)
  File "/home/yaroslav/.local/lib/python3.8/site-packages/django/template/loader_tags.py", line 150, in render
    return compiled_parent._render(context)
  File "/home/yaroslav/.local/lib/python3.8/site-packages/django/template/base.py", line 162, in _render
    return self.nodelist.render(context)
  File "/home/yaroslav/.local/lib/python3.8/site-packages/django/template/base.py", line 938, in render
    bit = node.render_annotated(context)
  File "/home/yaroslav/.local/lib/python3.8/site-packages/django/template/base.py", line 905, in render_annotated
    return self.render(context)
  File "/home/yaroslav/.local/lib/python3.8/site-packages/django/template/loader_tags.py", line 62, in render
    result = block.nodelist.render(context)
  File "/home/yaroslav/.local/lib/python3.8/site-packages/django/template/base.py", line 938, in render
    bit = node.render_annotated(context)
  File "/home/yaroslav/.local/lib/python3.8/site-packages/django/template/base.py", line 905, in render_annotated
    return self.render(context)
  File "/home/yaroslav/.local/lib/python3.8/site-packages/django/template/defaulttags.py", line 446, in render
    url = reverse(view_name, args=args, kwargs=kwargs, current_app=current_app)
  File "/home/yaroslav/.local/lib/python3.8/site-packages/django/urls/base.py", line 86, in reverse
    return resolver._reverse_with_prefix(view, prefix, *args, **kwargs)
  File "/home/yaroslav/.local/lib/python3.8/site-packages/django/urls/resolvers.py", line 694, in _reverse_with_prefix
    raise NoReverseMatch(msg)
django.urls.exceptions.NoReverseMatch: Reverse for 'sort_most_viewed_up' with keyword arguments '{'place': ''}' not found. 1 pattern(s) tried: ['sort_most_viewed_up/(?P<place>[^/]+)$']
2021-11-07 21:01:16,973  django.request ERROR    <--> Internal Server Error: /sort_most_viewed_down/home
Traceback (most recent call last):
  File "/home/yaroslav/.local/lib/python3.8/site-packages/django/core/handlers/exception.py", line 47, in inner
    response = get_response(request)
  File "/home/yaroslav/.local/lib/python3.8/site-packages/django/core/handlers/base.py", line 204, in _get_response
    response = response.render()
  File "/home/yaroslav/.local/lib/python3.8/site-packages/django/template/response.py", line 105, in render
    self.content = self.rendered_content
  File "/home/yaroslav/.local/lib/python3.8/site-packages/django/template/response.py", line 83, in rendered_content
    return template.render(context, self._request)
  File "/home/yaroslav/.local/lib/python3.8/site-packages/django/template/backends/django.py", line 61, in render
    return self.template.render(context)
  File "/home/yaroslav/.local/lib/python3.8/site-packages/django/template/base.py", line 170, in render
    return self._render(context)
  File "/home/yaroslav/.local/lib/python3.8/site-packages/django/template/base.py", line 162, in _render
    return self.nodelist.render(context)
  File "/home/yaroslav/.local/lib/python3.8/site-packages/django/template/base.py", line 938, in render
    bit = node.render_annotated(context)
  File "/home/yaroslav/.local/lib/python3.8/site-packages/django/template/base.py", line 905, in render_annotated
    return self.render(context)
  File "/home/yaroslav/.local/lib/python3.8/site-packages/django/template/loader_tags.py", line 150, in render
    return compiled_parent._render(context)
  File "/home/yaroslav/.local/lib/python3.8/site-packages/django/template/base.py", line 162, in _render
    return self.nodelist.render(context)
  File "/home/yaroslav/.local/lib/python3.8/site-packages/django/template/base.py", line 938, in render
    bit = node.render_annotated(context)
  File "/home/yaroslav/.local/lib/python3.8/site-packages/django/template/base.py", line 905, in render_annotated
    return self.render(context)
  File "/home/yaroslav/.local/lib/python3.8/site-packages/django/template/loader_tags.py", line 150, in render
    return compiled_parent._render(context)
  File "/home/yaroslav/.local/lib/python3.8/site-packages/django/template/base.py", line 162, in _render
    return self.nodelist.render(context)
  File "/home/yaroslav/.local/lib/python3.8/site-packages/django/template/base.py", line 938, in render
    bit = node.render_annotated(context)
  File "/home/yaroslav/.local/lib/python3.8/site-packages/django/template/base.py", line 905, in render_annotated
    return self.render(context)
  File "/home/yaroslav/.local/lib/python3.8/site-packages/django/template/loader_tags.py", line 62, in render
    result = block.nodelist.render(context)
  File "/home/yaroslav/.local/lib/python3.8/site-packages/django/template/base.py", line 938, in render
    bit = node.render_annotated(context)
  File "/home/yaroslav/.local/lib/python3.8/site-packages/django/template/base.py", line 905, in render_annotated
    return self.render(context)
  File "/home/yaroslav/.local/lib/python3.8/site-packages/django/template/defaulttags.py", line 446, in render
    url = reverse(view_name, args=args, kwargs=kwargs, current_app=current_app)
  File "/home/yaroslav/.local/lib/python3.8/site-packages/django/urls/base.py", line 86, in reverse
    return resolver._reverse_with_prefix(view, prefix, *args, **kwargs)
  File "/home/yaroslav/.local/lib/python3.8/site-packages/django/urls/resolvers.py", line 694, in _reverse_with_prefix
    raise NoReverseMatch(msg)
django.urls.exceptions.NoReverseMatch: Reverse for 'sort_most_viewed_up' with keyword arguments '{'place': ''}' not found. 1 pattern(s) tried: ['sort_most_viewed_up/(?P<place>[^/]+)$']
2021-11-07 21:01:53,338  django.request ERROR    <--> Internal Server Error: /sort_most_viewed_down/home
Traceback (most recent call last):
  File "/home/yaroslav/.local/lib/python3.8/site-packages/django/core/handlers/exception.py", line 47, in inner
    response = get_response(request)
  File "/home/yaroslav/.local/lib/python3.8/site-packages/django/core/handlers/base.py", line 204, in _get_response
    response = response.render()
  File "/home/yaroslav/.local/lib/python3.8/site-packages/django/template/response.py", line 105, in render
    self.content = self.rendered_content
  File "/home/yaroslav/.local/lib/python3.8/site-packages/django/template/response.py", line 83, in rendered_content
    return template.render(context, self._request)
  File "/home/yaroslav/.local/lib/python3.8/site-packages/django/template/backends/django.py", line 61, in render
    return self.template.render(context)
  File "/home/yaroslav/.local/lib/python3.8/site-packages/django/template/base.py", line 170, in render
    return self._render(context)
  File "/home/yaroslav/.local/lib/python3.8/site-packages/django/template/base.py", line 162, in _render
    return self.nodelist.render(context)
  File "/home/yaroslav/.local/lib/python3.8/site-packages/django/template/base.py", line 938, in render
    bit = node.render_annotated(context)
  File "/home/yaroslav/.local/lib/python3.8/site-packages/django/template/base.py", line 905, in render_annotated
    return self.render(context)
  File "/home/yaroslav/.local/lib/python3.8/site-packages/django/template/loader_tags.py", line 150, in render
    return compiled_parent._render(context)
  File "/home/yaroslav/.local/lib/python3.8/site-packages/django/template/base.py", line 162, in _render
    return self.nodelist.render(context)
  File "/home/yaroslav/.local/lib/python3.8/site-packages/django/template/base.py", line 938, in render
    bit = node.render_annotated(context)
  File "/home/yaroslav/.local/lib/python3.8/site-packages/django/template/base.py", line 905, in render_annotated
    return self.render(context)
  File "/home/yaroslav/.local/lib/python3.8/site-packages/django/template/loader_tags.py", line 150, in render
    return compiled_parent._render(context)
  File "/home/yaroslav/.local/lib/python3.8/site-packages/django/template/base.py", line 162, in _render
    return self.nodelist.render(context)
  File "/home/yaroslav/.local/lib/python3.8/site-packages/django/template/base.py", line 938, in render
    bit = node.render_annotated(context)
  File "/home/yaroslav/.local/lib/python3.8/site-packages/django/template/base.py", line 905, in render_annotated
    return self.render(context)
  File "/home/yaroslav/.local/lib/python3.8/site-packages/django/template/loader_tags.py", line 62, in render
    result = block.nodelist.render(context)
  File "/home/yaroslav/.local/lib/python3.8/site-packages/django/template/base.py", line 938, in render
    bit = node.render_annotated(context)
  File "/home/yaroslav/.local/lib/python3.8/site-packages/django/template/base.py", line 905, in render_annotated
    return self.render(context)
  File "/home/yaroslav/.local/lib/python3.8/site-packages/django/template/defaulttags.py", line 446, in render
    url = reverse(view_name, args=args, kwargs=kwargs, current_app=current_app)
  File "/home/yaroslav/.local/lib/python3.8/site-packages/django/urls/base.py", line 86, in reverse
    return resolver._reverse_with_prefix(view, prefix, *args, **kwargs)
  File "/home/yaroslav/.local/lib/python3.8/site-packages/django/urls/resolvers.py", line 694, in _reverse_with_prefix
    raise NoReverseMatch(msg)
django.urls.exceptions.NoReverseMatch: Reverse for 'sort_most_viewed_up' with keyword arguments '{'place': ''}' not found. 1 pattern(s) tried: ['sort_most_viewed_up/(?P<place>[^/]+)$']
2021-11-07 21:02:06,836  django.request ERROR    <--> Internal Server Error: /sort_most_viewed_down/home
Traceback (most recent call last):
  File "/home/yaroslav/.local/lib/python3.8/site-packages/django/core/handlers/exception.py", line 47, in inner
    response = get_response(request)
  File "/home/yaroslav/.local/lib/python3.8/site-packages/django/core/handlers/base.py", line 204, in _get_response
    response = response.render()
  File "/home/yaroslav/.local/lib/python3.8/site-packages/django/template/response.py", line 105, in render
    self.content = self.rendered_content
  File "/home/yaroslav/.local/lib/python3.8/site-packages/django/template/response.py", line 83, in rendered_content
    return template.render(context, self._request)
  File "/home/yaroslav/.local/lib/python3.8/site-packages/django/template/backends/django.py", line 61, in render
    return self.template.render(context)
  File "/home/yaroslav/.local/lib/python3.8/site-packages/django/template/base.py", line 170, in render
    return self._render(context)
  File "/home/yaroslav/.local/lib/python3.8/site-packages/django/template/base.py", line 162, in _render
    return self.nodelist.render(context)
  File "/home/yaroslav/.local/lib/python3.8/site-packages/django/template/base.py", line 938, in render
    bit = node.render_annotated(context)
  File "/home/yaroslav/.local/lib/python3.8/site-packages/django/template/base.py", line 905, in render_annotated
    return self.render(context)
  File "/home/yaroslav/.local/lib/python3.8/site-packages/django/template/loader_tags.py", line 150, in render
    return compiled_parent._render(context)
  File "/home/yaroslav/.local/lib/python3.8/site-packages/django/template/base.py", line 162, in _render
    return self.nodelist.render(context)
  File "/home/yaroslav/.local/lib/python3.8/site-packages/django/template/base.py", line 938, in render
    bit = node.render_annotated(context)
  File "/home/yaroslav/.local/lib/python3.8/site-packages/django/template/base.py", line 905, in render_annotated
    return self.render(context)
  File "/home/yaroslav/.local/lib/python3.8/site-packages/django/template/loader_tags.py", line 150, in render
    return compiled_parent._render(context)
  File "/home/yaroslav/.local/lib/python3.8/site-packages/django/template/base.py", line 162, in _render
    return self.nodelist.render(context)
  File "/home/yaroslav/.local/lib/python3.8/site-packages/django/template/base.py", line 938, in render
    bit = node.render_annotated(context)
  File "/home/yaroslav/.local/lib/python3.8/site-packages/django/template/base.py", line 905, in render_annotated
    return self.render(context)
  File "/home/yaroslav/.local/lib/python3.8/site-packages/django/template/loader_tags.py", line 62, in render
    result = block.nodelist.render(context)
  File "/home/yaroslav/.local/lib/python3.8/site-packages/django/template/base.py", line 938, in render
    bit = node.render_annotated(context)
  File "/home/yaroslav/.local/lib/python3.8/site-packages/django/template/base.py", line 905, in render_annotated
    return self.render(context)
  File "/home/yaroslav/.local/lib/python3.8/site-packages/django/template/defaulttags.py", line 446, in render
    url = reverse(view_name, args=args, kwargs=kwargs, current_app=current_app)
  File "/home/yaroslav/.local/lib/python3.8/site-packages/django/urls/base.py", line 86, in reverse
    return resolver._reverse_with_prefix(view, prefix, *args, **kwargs)
  File "/home/yaroslav/.local/lib/python3.8/site-packages/django/urls/resolvers.py", line 694, in _reverse_with_prefix
    raise NoReverseMatch(msg)
django.urls.exceptions.NoReverseMatch: Reverse for 'sort_most_viewed_up' with keyword arguments '{'place': ''}' not found. 1 pattern(s) tried: ['sort_most_viewed_up/(?P<place>[^/]+)$']
2021-11-07 21:02:33,768  django.request ERROR    <--> Internal Server Error: /sort_most_viewed_up/favicon.ico
Traceback (most recent call last):
  File "/home/yaroslav/.local/lib/python3.8/site-packages/django/core/handlers/exception.py", line 47, in inner
    response = get_response(request)
  File "/home/yaroslav/.local/lib/python3.8/site-packages/django/core/handlers/base.py", line 181, in _get_response
    response = wrapped_callback(request, *callback_args, **callback_kwargs)
  File "/home/yaroslav/.local/lib/python3.8/site-packages/django/views/generic/base.py", line 70, in view
    return self.dispatch(request, *args, **kwargs)
  File "/home/yaroslav/.local/lib/python3.8/site-packages/django/views/generic/base.py", line 98, in dispatch
    return handler(request, *args, **kwargs)
  File "/home/yaroslav/.local/lib/python3.8/site-packages/django/views/generic/list.py", line 157, in get
    context = self.get_context_data()
  File "/home/yaroslav/Programming/Python/Django/StoreProject/market/store/services/order.py", line 27, in get_context_data
    context = super().get_context_data(**kwargs)  # like dynamic list
  File "/home/yaroslav/.local/lib/python3.8/site-packages/django/views/generic/list.py", line 119, in get_context_data
    paginator, page, queryset, is_paginated = self.paginate_queryset(queryset, page_size)
  File "/home/yaroslav/.local/lib/python3.8/site-packages/django/views/generic/list.py", line 69, in paginate_queryset
    page = paginator.page(page_number)
  File "/home/yaroslav/.local/lib/python3.8/site-packages/django/core/paginator.py", line 76, in page
    number = self.validate_number(number)
  File "/home/yaroslav/.local/lib/python3.8/site-packages/django/core/paginator.py", line 54, in validate_number
    if number > self.num_pages:
  File "/home/yaroslav/.local/lib/python3.8/site-packages/django/utils/functional.py", line 48, in __get__
    res = instance.__dict__[self.name] = self.func(instance)
  File "/home/yaroslav/.local/lib/python3.8/site-packages/django/core/paginator.py", line 103, in num_pages
    if self.count == 0 and not self.allow_empty_first_page:
  File "/home/yaroslav/.local/lib/python3.8/site-packages/django/utils/functional.py", line 48, in __get__
    res = instance.__dict__[self.name] = self.func(instance)
  File "/home/yaroslav/.local/lib/python3.8/site-packages/django/core/paginator.py", line 98, in count
    return len(self.object_list)
TypeError: object of type 'NoneType' has no len()
2021-11-07 21:04:27,661  django.request ERROR    <--> Internal Server Error: /sort_most_viewed_down/home
Traceback (most recent call last):
  File "/home/yaroslav/.local/lib/python3.8/site-packages/django/core/handlers/exception.py", line 47, in inner
    response = get_response(request)
  File "/home/yaroslav/.local/lib/python3.8/site-packages/django/core/handlers/base.py", line 204, in _get_response
    response = response.render()
  File "/home/yaroslav/.local/lib/python3.8/site-packages/django/template/response.py", line 105, in render
    self.content = self.rendered_content
  File "/home/yaroslav/.local/lib/python3.8/site-packages/django/template/response.py", line 83, in rendered_content
    return template.render(context, self._request)
  File "/home/yaroslav/.local/lib/python3.8/site-packages/django/template/backends/django.py", line 61, in render
    return self.template.render(context)
  File "/home/yaroslav/.local/lib/python3.8/site-packages/django/template/base.py", line 170, in render
    return self._render(context)
  File "/home/yaroslav/.local/lib/python3.8/site-packages/django/template/base.py", line 162, in _render
    return self.nodelist.render(context)
  File "/home/yaroslav/.local/lib/python3.8/site-packages/django/template/base.py", line 938, in render
    bit = node.render_annotated(context)
  File "/home/yaroslav/.local/lib/python3.8/site-packages/django/template/base.py", line 905, in render_annotated
    return self.render(context)
  File "/home/yaroslav/.local/lib/python3.8/site-packages/django/template/loader_tags.py", line 150, in render
    return compiled_parent._render(context)
  File "/home/yaroslav/.local/lib/python3.8/site-packages/django/template/base.py", line 162, in _render
    return self.nodelist.render(context)
  File "/home/yaroslav/.local/lib/python3.8/site-packages/django/template/base.py", line 938, in render
    bit = node.render_annotated(context)
  File "/home/yaroslav/.local/lib/python3.8/site-packages/django/template/base.py", line 905, in render_annotated
    return self.render(context)
  File "/home/yaroslav/.local/lib/python3.8/site-packages/django/template/loader_tags.py", line 150, in render
    return compiled_parent._render(context)
  File "/home/yaroslav/.local/lib/python3.8/site-packages/django/template/base.py", line 162, in _render
    return self.nodelist.render(context)
  File "/home/yaroslav/.local/lib/python3.8/site-packages/django/template/base.py", line 938, in render
    bit = node.render_annotated(context)
  File "/home/yaroslav/.local/lib/python3.8/site-packages/django/template/base.py", line 905, in render_annotated
    return self.render(context)
  File "/home/yaroslav/.local/lib/python3.8/site-packages/django/template/loader_tags.py", line 62, in render
    result = block.nodelist.render(context)
  File "/home/yaroslav/.local/lib/python3.8/site-packages/django/template/base.py", line 938, in render
    bit = node.render_annotated(context)
  File "/home/yaroslav/.local/lib/python3.8/site-packages/django/template/base.py", line 905, in render_annotated
    return self.render(context)
  File "/home/yaroslav/.local/lib/python3.8/site-packages/django/template/defaulttags.py", line 446, in render
    url = reverse(view_name, args=args, kwargs=kwargs, current_app=current_app)
  File "/home/yaroslav/.local/lib/python3.8/site-packages/django/urls/base.py", line 86, in reverse
    return resolver._reverse_with_prefix(view, prefix, *args, **kwargs)
  File "/home/yaroslav/.local/lib/python3.8/site-packages/django/urls/resolvers.py", line 694, in _reverse_with_prefix
    raise NoReverseMatch(msg)
django.urls.exceptions.NoReverseMatch: Reverse for 'sort_most_viewed_up' with keyword arguments '{'place': ''}' not found. 1 pattern(s) tried: ['sort_most_viewed_up/(?P<place>[^/]+)$']
2021-11-07 21:04:56,289  django.request ERROR    <--> Internal Server Error: /sort_most_viewed_down/home
Traceback (most recent call last):
  File "/home/yaroslav/.local/lib/python3.8/site-packages/django/core/handlers/exception.py", line 47, in inner
    response = get_response(request)
  File "/home/yaroslav/.local/lib/python3.8/site-packages/django/core/handlers/base.py", line 181, in _get_response
    response = wrapped_callback(request, *callback_args, **callback_kwargs)
  File "/home/yaroslav/.local/lib/python3.8/site-packages/django/views/generic/base.py", line 70, in view
    return self.dispatch(request, *args, **kwargs)
  File "/home/yaroslav/.local/lib/python3.8/site-packages/django/views/generic/base.py", line 98, in dispatch
    return handler(request, *args, **kwargs)
  File "/home/yaroslav/.local/lib/python3.8/site-packages/django/views/generic/list.py", line 157, in get
    context = self.get_context_data()
  File "/home/yaroslav/Programming/Python/Django/StoreProject/market/store/services/order.py", line 53, in get_context_data
    place=self.place if not None else "home",
AttributeError: 'ProductViewsDown' object has no attribute 'place'
2021-11-07 21:13:29,948  django.request ERROR    <--> Internal Server Error: /sort_most_viewed_down/home
Traceback (most recent call last):
  File "/home/yaroslav/.local/lib/python3.8/site-packages/django/core/handlers/exception.py", line 47, in inner
    response = get_response(request)
  File "/home/yaroslav/.local/lib/python3.8/site-packages/django/core/handlers/base.py", line 181, in _get_response
    response = wrapped_callback(request, *callback_args, **callback_kwargs)
  File "/home/yaroslav/.local/lib/python3.8/site-packages/django/views/generic/base.py", line 70, in view
    return self.dispatch(request, *args, **kwargs)
  File "/home/yaroslav/.local/lib/python3.8/site-packages/django/views/generic/base.py", line 98, in dispatch
    return handler(request, *args, **kwargs)
  File "/home/yaroslav/.local/lib/python3.8/site-packages/django/views/generic/list.py", line 142, in get
    self.object_list = self.get_queryset()
  File "/home/yaroslav/Programming/Python/Django/StoreProject/market/store/services/order.py", line 46, in get_queryset
    UserOrderHistory.objects.create(user=self.request.user, order_place=self.place)
  File "/home/yaroslav/.local/lib/python3.8/site-packages/django/db/models/manager.py", line 85, in manager_method
    return getattr(self.get_queryset(), name)(*args, **kwargs)
  File "/home/yaroslav/.local/lib/python3.8/site-packages/django/db/models/query.py", line 451, in create
    obj = self.model(**kwargs)
  File "/home/yaroslav/.local/lib/python3.8/site-packages/django/db/models/base.py", line 485, in __init__
    _setattr(self, field.name, rel_obj)
  File "/home/yaroslav/.local/lib/python3.8/site-packages/django/db/models/fields/related_descriptors.py", line 215, in __set__
    raise ValueError(
ValueError: Cannot assign "<SimpleLazyObject: <django.contrib.auth.models.AnonymousUser object at 0x7f711879bfd0>>": "UserOrderHistory.user" must be a "User" instance.
2021-11-07 21:14:49,860  django.request ERROR    <--> Internal Server Error: /sort_most_viewed_down/home
Traceback (most recent call last):
  File "/home/yaroslav/.local/lib/python3.8/site-packages/django/core/handlers/exception.py", line 47, in inner
    response = get_response(request)
  File "/home/yaroslav/.local/lib/python3.8/site-packages/django/core/handlers/base.py", line 181, in _get_response
    response = wrapped_callback(request, *callback_args, **callback_kwargs)
  File "/home/yaroslav/.local/lib/python3.8/site-packages/django/views/generic/base.py", line 70, in view
    return self.dispatch(request, *args, **kwargs)
  File "/home/yaroslav/.local/lib/python3.8/site-packages/django/views/generic/base.py", line 98, in dispatch
    return handler(request, *args, **kwargs)
  File "/home/yaroslav/.local/lib/python3.8/site-packages/django/views/generic/list.py", line 142, in get
    self.object_list = self.get_queryset()
  File "/home/yaroslav/Programming/Python/Django/StoreProject/market/store/services/order.py", line 46, in get_queryset
    UserOrderHistory.objects.create(user=self.request.user, order_place=self.place)
  File "/home/yaroslav/.local/lib/python3.8/site-packages/django/db/models/manager.py", line 85, in manager_method
    return getattr(self.get_queryset(), name)(*args, **kwargs)
  File "/home/yaroslav/.local/lib/python3.8/site-packages/django/db/models/query.py", line 451, in create
    obj = self.model(**kwargs)
  File "/home/yaroslav/.local/lib/python3.8/site-packages/django/db/models/base.py", line 485, in __init__
    _setattr(self, field.name, rel_obj)
  File "/home/yaroslav/.local/lib/python3.8/site-packages/django/db/models/fields/related_descriptors.py", line 215, in __set__
    raise ValueError(
ValueError: Cannot assign "<SimpleLazyObject: <django.contrib.auth.models.AnonymousUser object at 0x7f71199c5430>>": "UserOrderHistory.user" must be a "User" instance.
2021-11-07 21:15:04,202  django.request ERROR    <--> Internal Server Error: /sort_most_viewed_down/home
Traceback (most recent call last):
  File "/home/yaroslav/.local/lib/python3.8/site-packages/django/core/handlers/exception.py", line 47, in inner
    response = get_response(request)
  File "/home/yaroslav/.local/lib/python3.8/site-packages/django/core/handlers/base.py", line 181, in _get_response
    response = wrapped_callback(request, *callback_args, **callback_kwargs)
  File "/home/yaroslav/.local/lib/python3.8/site-packages/django/views/generic/base.py", line 70, in view
    return self.dispatch(request, *args, **kwargs)
  File "/home/yaroslav/.local/lib/python3.8/site-packages/django/views/generic/base.py", line 98, in dispatch
    return handler(request, *args, **kwargs)
  File "/home/yaroslav/.local/lib/python3.8/site-packages/django/views/generic/list.py", line 142, in get
    self.object_list = self.get_queryset()
  File "/home/yaroslav/Programming/Python/Django/StoreProject/market/store/services/order.py", line 46, in get_queryset
    UserOrderHistory.objects.create(user=self.request.user, order_place=self.place)
  File "/home/yaroslav/.local/lib/python3.8/site-packages/django/db/models/manager.py", line 85, in manager_method
    return getattr(self.get_queryset(), name)(*args, **kwargs)
  File "/home/yaroslav/.local/lib/python3.8/site-packages/django/db/models/query.py", line 451, in create
    obj = self.model(**kwargs)
  File "/home/yaroslav/.local/lib/python3.8/site-packages/django/db/models/base.py", line 485, in __init__
    _setattr(self, field.name, rel_obj)
  File "/home/yaroslav/.local/lib/python3.8/site-packages/django/db/models/fields/related_descriptors.py", line 215, in __set__
    raise ValueError(
ValueError: Cannot assign "<SimpleLazyObject: <django.contrib.auth.models.AnonymousUser object at 0x7f7118721af0>>": "UserOrderHistory.user" must be a "User" instance.
